  0%|                                                 | 0/19899 [00:00<?, ?it/s]
Traceback (most recent call last):
  File "/Users/fridadesigley/edge_root/edge/main.py", line 65, in <module>
    evaluation = deep_eval(model, data_load_dict=data_loader)
  File "/Users/fridadesigley/edge_root/edge/inference.py", line 433, in deep_eval
    for data, label, fid in tqdm(data_load_dict['test']):
  File "/Users/fridadesigley/.pyenv/versions/edge/lib/python3.10/site-packages/tqdm/std.py", line 1195, in __iter__
    for obj in iterable:
  File "/Users/fridadesigley/.pyenv/versions/edge/lib/python3.10/site-packages/torch/utils/data/dataloader.py", line 652, in __next__
    data = self._next_data()
  File "/Users/fridadesigley/.pyenv/versions/edge/lib/python3.10/site-packages/torch/utils/data/dataloader.py", line 692, in _next_data
    data = self._dataset_fetcher.fetch(index)  # may raise StopIteration
  File "/Users/fridadesigley/.pyenv/versions/edge/lib/python3.10/site-packages/torch/utils/data/_utils/fetch.py", line 51, in fetch
    data = self.dataset[possibly_batched_index]
  File "/Users/fridadesigley/edge_root/edge/ava.py", line 732, in __getitem__
    img = read(img)
  File "/Users/fridadesigley/edge_root/edge/ava.py", line 730, in read
    os.readlink(fid)), cv2.COLOR_BGR2RGB).astype(np.uint8)
FileNotFoundError: [Errno 2] No such file or directory: '../data/test/871233.jpg'