2022-08-10 10:29:50,969 INFO    MainThread:67862 [internal.py:wandb_internal():90] W&B internal server running at pid: 67862, started at: 2022-08-10 10:29:50.969140
2022-08-10 10:29:50,969 INFO    WriterThread:67862 [datastore.py:open_for_write():75] open: /Users/fridadesigley/edge/wandb/run-20220810_102950-1zwtbsva/run-1zwtbsva.wandb
2022-08-10 10:29:50,971 DEBUG   SenderThread:67862 [sender.py:send():236] send: header
2022-08-10 10:29:50,971 DEBUG   SenderThread:67862 [sender.py:send():236] send: run
2022-08-10 10:29:54,693 ERROR   SenderThread:67862 [retry.py:__call__():132] Retry attempt failed:
Traceback (most recent call last):
  File "/Users/fridadesigley/.pyenv/versions/edge/lib/python3.10/site-packages/urllib3/connection.py", line 174, in _new_conn
    conn = connection.create_connection(
  File "/Users/fridadesigley/.pyenv/versions/edge/lib/python3.10/site-packages/urllib3/util/connection.py", line 95, in create_connection
    raise err
  File "/Users/fridadesigley/.pyenv/versions/edge/lib/python3.10/site-packages/urllib3/util/connection.py", line 85, in create_connection
    sock.connect(sa)
ConnectionRefusedError: [Errno 61] Connection refused

During handling of the above exception, another exception occurred:

Traceback (most recent call last):
  File "/Users/fridadesigley/.pyenv/versions/edge/lib/python3.10/site-packages/urllib3/connectionpool.py", line 703, in urlopen
    httplib_response = self._make_request(
  File "/Users/fridadesigley/.pyenv/versions/edge/lib/python3.10/site-packages/urllib3/connectionpool.py", line 398, in _make_request
    conn.request(method, url, **httplib_request_kw)
  File "/Users/fridadesigley/.pyenv/versions/edge/lib/python3.10/site-packages/urllib3/connection.py", line 239, in request
    super(HTTPConnection, self).request(method, url, body=body, headers=headers)
  File "/Users/fridadesigley/.pyenv/versions/3.10.4/lib/python3.10/http/client.py", line 1282, in request
    self._send_request(method, url, body, headers, encode_chunked)
  File "/Users/fridadesigley/.pyenv/versions/3.10.4/lib/python3.10/http/client.py", line 1328, in _send_request
    self.endheaders(body, encode_chunked=encode_chunked)
  File "/Users/fridadesigley/.pyenv/versions/3.10.4/lib/python3.10/http/client.py", line 1277, in endheaders
    self._send_output(message_body, encode_chunked=encode_chunked)
  File "/Users/fridadesigley/.pyenv/versions/3.10.4/lib/python3.10/http/client.py", line 1037, in _send_output
    self.send(msg)
  File "/Users/fridadesigley/.pyenv/versions/3.10.4/lib/python3.10/http/client.py", line 975, in send
    self.connect()
  File "/Users/fridadesigley/.pyenv/versions/edge/lib/python3.10/site-packages/urllib3/connection.py", line 205, in connect
    conn = self._new_conn()
  File "/Users/fridadesigley/.pyenv/versions/edge/lib/python3.10/site-packages/urllib3/connection.py", line 186, in _new_conn
    raise NewConnectionError(
urllib3.exceptions.NewConnectionError: <urllib3.connection.HTTPConnection object at 0x116e2d180>: Failed to establish a new connection: [Errno 61] Connection refused

During handling of the above exception, another exception occurred:

Traceback (most recent call last):
  File "/Users/fridadesigley/.pyenv/versions/edge/lib/python3.10/site-packages/requests/adapters.py", line 489, in send
    resp = conn.urlopen(
  File "/Users/fridadesigley/.pyenv/versions/edge/lib/python3.10/site-packages/urllib3/connectionpool.py", line 787, in urlopen
    retries = retries.increment(
  File "/Users/fridadesigley/.pyenv/versions/edge/lib/python3.10/site-packages/urllib3/util/retry.py", line 592, in increment
    raise MaxRetryError(_pool, url, error or ResponseError(cause))
urllib3.exceptions.MaxRetryError: HTTPConnectionPool(host='localhost', port=8080): Max retries exceeded with url: /graphql (Caused by NewConnectionError('<urllib3.connection.HTTPConnection object at 0x116e2d180>: Failed to establish a new connection: [Errno 61] Connection refused'))

During handling of the above exception, another exception occurred:

Traceback (most recent call last):
  File "/Users/fridadesigley/.pyenv/versions/edge/lib/python3.10/site-packages/wandb/sdk/lib/retry.py", line 108, in __call__
    result = self._call_fn(*args, **kwargs)
  File "/Users/fridadesigley/.pyenv/versions/edge/lib/python3.10/site-packages/wandb/sdk/internal/internal_api.py", line 158, in execute
    return self.client.execute(*args, **kwargs)
  File "/Users/fridadesigley/.pyenv/versions/edge/lib/python3.10/site-packages/wandb/vendor/gql-0.2.0/wandb_gql/client.py", line 52, in execute
    result = self._get_result(document, *args, **kwargs)
  File "/Users/fridadesigley/.pyenv/versions/edge/lib/python3.10/site-packages/wandb/vendor/gql-0.2.0/wandb_gql/client.py", line 60, in _get_result
    return self.transport.execute(document, *args, **kwargs)
  File "/Users/fridadesigley/.pyenv/versions/edge/lib/python3.10/site-packages/wandb/vendor/gql-0.2.0/wandb_gql/transport/requests.py", line 38, in execute
    request = requests.post(self.url, **post_args)
  File "/Users/fridadesigley/.pyenv/versions/edge/lib/python3.10/site-packages/requests/api.py", line 115, in post
    return request("post", url, data=data, json=json, **kwargs)
  File "/Users/fridadesigley/.pyenv/versions/edge/lib/python3.10/site-packages/requests/api.py", line 59, in request
    return session.request(method=method, url=url, **kwargs)
  File "/Users/fridadesigley/.pyenv/versions/edge/lib/python3.10/site-packages/requests/sessions.py", line 587, in request
    resp = self.send(prep, **send_kwargs)
  File "/Users/fridadesigley/.pyenv/versions/edge/lib/python3.10/site-packages/requests/sessions.py", line 701, in send
    r = adapter.send(request, **kwargs)
  File "/Users/fridadesigley/.pyenv/versions/edge/lib/python3.10/site-packages/requests/adapters.py", line 565, in send
    raise ConnectionError(e, request=request)
requests.exceptions.ConnectionError: HTTPConnectionPool(host='localhost', port=8080): Max retries exceeded with url: /graphql (Caused by NewConnectionError('<urllib3.connection.HTTPConnection object at 0x116e2d180>: Failed to establish a new connection: [Errno 61] Connection refused'))
2022-08-10 10:30:20,674 DEBUG   HandlerThread:67862 [handler.py:handle_request():140] handle_request: shutdown
2022-08-10 10:30:20,675 INFO    HandlerThread:67862 [handler.py:finish():806] shutting down handler
2022-08-10 10:30:21,069 INFO    WriterThread:67862 [datastore.py:close():279] close: /Users/fridadesigley/edge/wandb/run-20220810_102950-1zwtbsva/run-1zwtbsva.wandb
2022-08-10 10:31:14,127 INFO    MainThread:67862 [internal.py:handle_exit():80] Internal process exited
